<?xml version="1.0"?>
<robot name="torso"
	xmlns:sensor="http://playerstage.sourceforge.net/gazebo/xmlschema/#sensor"
	xmlns:controller="http://playerstage.sourceforge.net/gazebo/xmlschema/#controller"
	xmlns:interface="http://playerstage.sourceforge.net/gazebo/xmlschema/#interface">

	<!-- ################################################################################# -->
	<!-- add links-->
	
	<!-- platform -->
	<link name="link_platform">
		<inertial>
			<origin xyz="0 0 0" rpy="0 0 0"/>
			<mass value="50"/>
			<inertia ixx="1"  ixy="0"  ixz="0" iyy="1" iyz="0" izz="1" />
		</inertial>
		<visual>
			<origin xyz="0 0 0.05" rpy="0 0 0" />
			<geometry>
<!--		        <box size="0.6 0.4 0.3"/> -->
				<mesh filename="package://cob3_defs/common/files/meshes/platform.stl" />
			</geometry>
		</visual>
		<collision>
			<origin xyz="0 0 0.05" rpy="0 0 0" />
			<geometry>
<!--		        <box size="0.6 0.4 0.3"/> -->
				<mesh filename="package://cob3_defs/common/files/meshes/platform.stl" />
			</geometry>
		</collision>
	</link>

	<!-- wheel front left -->
	<link name="link_steerFL">
		<inertial>
			<origin xyz="0 0 0" rpy="0 0 0"/>
			<mass value="3"/>
			<inertia ixx="1"  ixy="0"  ixz="0" iyy="1" iyz="0" izz="1" />
		</inertial>
		<visual>
			<origin xyz="0 0 -0.05" rpy="0 0 0" />
			<geometry>
		        <box size="0.1 0.1 0.1"/>
			</geometry>
		</visual>
		<collision>
			<origin xyz="0 0 -0.05" rpy="0 0 0" />
			<geometry>
		        <box size="0.1 0.1 0.1"/>
			</geometry>
		</collision>
	</link>

	<link name="link_wheelFL">
		<inertial>
			<origin xyz="0 0 0" rpy="0 0 0"/>
			<mass value="1"/>
			<inertia ixx="1"  ixy="0"  ixz="0" iyy="1" iyz="0" izz="1" />
		</inertial>
		<visual>
			<origin xyz="0 0 0.0025" rpy="1.57 0 0" />
			<geometry>
					<cylinder radius="0.1" length="0.05"/>
			</geometry>
		</visual>
		<collision>
			<origin xyz="0 0 0.0025" rpy="1.57 0 0" />
			<geometry>
		        <cylinder radius="0.1" length="0.05"/>
			</geometry>
		</collision>
	</link>
	
	<!-- wheel front right -->
	<link name="link_steerFR">
		<inertial>
			<origin xyz="0 0 0" rpy="0 0 0"/>
			<mass value="3"/>
			<inertia ixx="1"  ixy="0"  ixz="0" iyy="1" iyz="0" izz="1" />
		</inertial>
		<visual>
			<origin xyz="0 0 -0.05" rpy="0 0 0" />
			<geometry>
		        <box size="0.1 0.1 0.1"/>
			</geometry>
		</visual>
		<collision>
			<origin xyz="0 0 -0.05" rpy="0 0 0" />
			<geometry>
		        <box size="0.1 0.1 0.1"/>
			</geometry>
		</collision>
	</link>

	<link name="link_wheelFR">
		<inertial>
			<origin xyz="0 0 0" rpy="0 0 0"/>
			<mass value="1"/>
			<inertia ixx="1"  ixy="0"  ixz="0" iyy="1" iyz="0" izz="1" />
		</inertial>
		<visual>
			<origin xyz="0 0 0.0025" rpy="1.57 0 0" />
			<geometry>
					<cylinder radius="0.1" length="0.05"/>
			</geometry>
		</visual>
		<collision>
			<origin xyz="0 0 0.0025" rpy="1.57 0 0" />
			<geometry>
		        <cylinder radius="0.1" length="0.05"/>
			</geometry>
		</collision>
	</link>	

	<!-- wheel rear left -->
	<link name="link_steerRL">
		<inertial>
			<origin xyz="0 0 0" rpy="0 0 0"/>
			<mass value="3"/>
			<inertia ixx="1"  ixy="0"  ixz="0" iyy="1" iyz="0" izz="1" />
		</inertial>
		<visual>
			<origin xyz="0 0 -0.05" rpy="0 0 0" />
			<geometry>
		        <box size="0.1 0.1 0.1"/>
			</geometry>
		</visual>
		<collision>
			<origin xyz="0 0 -0.05" rpy="0 0 0" />
			<geometry>
		        <box size="0.1 0.1 0.1"/>
			</geometry>
		</collision>
	</link>

	<link name="link_wheelRL">
		<inertial>
			<origin xyz="0 0 0" rpy="0 0 0"/>
			<mass value="1"/>
			<inertia ixx="1"  ixy="0"  ixz="0" iyy="1" iyz="0" izz="1" />
		</inertial>
		<visual>
			<origin xyz="0 0 0.0025" rpy="1.57 0 0" />
			<geometry>
					<cylinder radius="0.1" length="0.05"/>
			</geometry>
		</visual>
		<collision>
			<origin xyz="0 0 0.0025" rpy="1.57 0 0" />
			<geometry>
		        <cylinder radius="0.1" length="0.05"/>
			</geometry>
		</collision>
	</link>
	
	<!-- wheel rear right -->
	<link name="link_steerRR">
		<inertial>
			<origin xyz="0 0 0" rpy="0 0 0"/>
			<mass value="3"/>
			<inertia ixx="1"  ixy="0"  ixz="0" iyy="1" iyz="0" izz="1" />
		</inertial>
		<visual>
			<origin xyz="0 0 -0.05" rpy="0 0 0" />
			<geometry>
		        <box size="0.1 0.1 0.1"/>
			</geometry>
		</visual>
		<collision>
			<origin xyz="0 0 -0.05" rpy="0 0 0" />
			<geometry>
		        <box size="0.1 0.1 0.1"/>
			</geometry>
		</collision>
	</link>

	<link name="link_wheelRR">
		<inertial>
			<origin xyz="0 0 0" rpy="0 0 0"/>
			<mass value="1"/>
			<inertia ixx="1"  ixy="0"  ixz="0" iyy="1" iyz="0" izz="1" />
		</inertial>
		<visual>
			<origin xyz="0 0 0.0025" rpy="1.57 0 0" />
			<geometry>
					<cylinder radius="0.1" length="0.05"/>
			</geometry>
		</visual>
		<collision>
			<origin xyz="0 0 0.0025" rpy="1.57 0 0" />
			<geometry>
		        <cylinder radius="0.1" length="0.05"/>
			</geometry>
		</collision>
	</link>

	<!-- define colors for links -->
	<gazebo reference="link_platform">
		<material>Gazebo/Grey</material>
		<turnGravityOff>false</turnGravityOff>
	</gazebo>

	<gazebo reference="link_steerFL">
		<material>Gazebo/Black</material>
		<turnGravityOff>false</turnGravityOff>
	</gazebo>

	<gazebo reference="link_wheelFL">
		<material>Gazebo/Red</material>
		<turnGravityOff>false</turnGravityOff>
	</gazebo>
	
	<gazebo reference="link_steerFR">
		<material>Gazebo/Black</material>
		<turnGravityOff>false</turnGravityOff>
	</gazebo>

	<gazebo reference="link_wheelFR">
		<material>Gazebo/Red</material>
		<turnGravityOff>false</turnGravityOff>
	</gazebo>
	
	<gazebo reference="link_steerRL">
		<material>Gazebo/Black</material>
		<turnGravityOff>false</turnGravityOff>
	</gazebo>

	<gazebo reference="link_wheelRL">
		<material>Gazebo/Red</material>
		<turnGravityOff>false</turnGravityOff>
	</gazebo>
	
	<gazebo reference="link_steerRR">
		<material>Gazebo/Black</material>
		<turnGravityOff>false</turnGravityOff>
	</gazebo>

	<gazebo reference="link_wheelRR">
		<material>Gazebo/Red</material>
		<turnGravityOff>false</turnGravityOff>
	</gazebo>

	<!-- ################################################################################# -->
	<!-- add joints -->
	
	<!-- wheel front left -->
	<joint name="joint_platform_steerFL" type="continuous">
		<origin xyz="0.3 0.2 0" rpy="0 0 0" />
		<parent link="link_platform"/>
		<child link="link_steerFL"/>
		<axis xyz="0 0 1" />
	    <calibration reference_position="0.0"/>
		<limit effort="100" lower="-1" upper="1" velocity="5"/>
	</joint>
	
	<joint name="joint_steerFL_wheelFL" type="continuous">
		<origin xyz="0 0 -0.2" rpy="0 0 0" />
		<parent link="link_steerFL"/>
		<child link="link_wheelFL"/>
		<axis xyz="0 1 0" />
	    <calibration reference_position="0.0"/>
		<limit effort="100" lower="-1" upper="1" velocity="5"/>
	</joint>

	<!-- wheel front right -->
	<joint name="joint_platform_steerFR" type="continuous">
		<origin xyz="0.3 -0.2 0" rpy="0 0 0" />
		<parent link="link_platform"/>
		<child link="link_steerFR"/>
		<axis xyz="0 0 1" />
	    <calibration reference_position="0.0"/>
		<limit effort="100" lower="-1" upper="1" velocity="5"/>
	</joint>
	
	<joint name="joint_steerFR_wheelFR" type="continuous">
		<origin xyz="0 0 -0.2" rpy="0 0 0" />
		<parent link="link_steerFR"/>
		<child link="link_wheelFR"/>
		<axis xyz="0 1 0" />
	    <calibration reference_position="0.0"/>
		<limit effort="100" lower="-1" upper="1" velocity="5"/>
	</joint>
	
	<!-- wheel rear left -->
	<joint name="joint_platform_steerRL" type="continuous">
		<origin xyz="-0.3 0.2 0" rpy="0 0 0" />
		<parent link="link_platform"/>
		<child link="link_steerRL"/>
		<axis xyz="0 0 1" />
	    <calibration reference_position="0.0"/>
		<limit effort="100" lower="-1" upper="1" velocity="5"/>
	</joint>
	
	<joint name="joint_steerRL_wheelRL" type="continuous">
		<origin xyz="0 0 -0.2" rpy="0 0 0" />
		<parent link="link_steerRL"/>
		<child link="link_wheelRL"/>
		<axis xyz="0 1 0" />
	    <calibration reference_position="0.0"/>
		<limit effort="100" lower="-1" upper="1" velocity="5"/>
	</joint>

	<!-- wheel rear right -->
	<joint name="joint_platform_steerRR" type="continuous">
		<origin xyz="-0.3 -0.2 0" rpy="0 0 0" />
		<parent link="link_platform"/>
		<child link="link_steerRR"/>
		<axis xyz="0 0 1" />
	    <calibration reference_position="0.0"/>
		<limit effort="100" lower="-1" upper="1" velocity="5"/>
	</joint>
	
	<joint name="joint_steerRR_wheelRR" type="continuous">
		<origin xyz="0 0 -0.2" rpy="0 0 0" />
		<parent link="link_steerRR"/>
		<child link="link_wheelRR"/>
		<axis xyz="0 1 0" />
	    <calibration reference_position="0.0"/>
		<limit effort="100" lower="-1" upper="1" velocity="5"/>
	</joint>

	<!-- ################################################################################# -->
	<!-- add transmissions -->
	
	<!-- wheel front left -->
	<transmission name="trans_platform_steerFL" type="SimpleTransmission">
		<actuator name="motor_platform_steerFL"/>
		<joint name="joint_platform_steerFL"/>
		<mechanicalReduction>1</mechanicalReduction>
	</transmission>

	<transmission name="trans_steerFL_wheelFL" type="SimpleTransmission">
		<actuator name="motor_steerFL_wheelFL"/>
		<joint name="joint_steerFL_wheelFL"/>
		<mechanicalReduction>1</mechanicalReduction>
	</transmission>
	
	<!-- wheel front right -->
	<transmission name="trans_platform_steerFR" type="SimpleTransmission">
		<actuator name="motor_platform_steerFR"/>
		<joint name="joint_platform_steerFR"/>
		<mechanicalReduction>1</mechanicalReduction>
	</transmission>

	<transmission name="trans_steerFR_wheelFR" type="SimpleTransmission">
		<actuator name="motor_steerFR_wheelFR"/>
		<joint name="joint_steerFR_wheelFR"/>
		<mechanicalReduction>1</mechanicalReduction>
	</transmission>
	
	<!-- wheel rear left -->
	<transmission name="trans_platform_steerRL" type="SimpleTransmission">
		<actuator name="motor_platform_steerRL"/>
		<joint name="joint_platform_steerRL"/>
		<mechanicalReduction>1</mechanicalReduction>
	</transmission>

	<transmission name="trans_steerRL_wheelRL" type="SimpleTransmission">
		<actuator name="motor_steerRL_wheelRL"/>
		<joint name="joint_steerRL_wheelRL"/>
		<mechanicalReduction>1</mechanicalReduction>
	</transmission>
	
	<!-- wheel rear right -->
	<transmission name="trans_platform_steerRR" type="SimpleTransmission">
		<actuator name="motor_platform_steerRR"/>
		<joint name="joint_platform_steerRR"/>
		<mechanicalReduction>1</mechanicalReduction>
	</transmission>

	<transmission name="trans_steerRR_wheelRR" type="SimpleTransmission">
		<actuator name="motor_steerRR_wheelRR"/>
		<joint name="joint_steerRR_wheelRR"/>
		<mechanicalReduction>1</mechanicalReduction>
	</transmission>

</robot>
