<?xml version="1.0"?>
<robot name="sdh"
	xmlns:sensor="http://playerstage.sourceforge.net/gazebo/xmlschema/#sensor"
	xmlns:controller="http://playerstage.sourceforge.net/gazebo/xmlschema/#controller"
	xmlns:interface="http://playerstage.sourceforge.net/gazebo/xmlschema/#interface">

	<!-- ################################################################################# -->
	<!-- add links-->
	
	<!-- palm -->
	<link name="link_palm">
		<inertial>
			<origin xyz="0 0 0" rpy="0 0 0"/>
			<mass value="1"/>
			<inertia ixx="1"  ixy="0"  ixz="0" iyy="1" iyz="0" izz="1" />
		</inertial>
		<visual>
			<origin xyz="0 0 0" rpy="0 0 0" />
			<geometry>
				<mesh filename="package://cob3_defs/common/files/meshes/palm.stl" />
			</geometry>
		</visual>
		<collision>
			<origin xyz="0 0 0" rpy="0 0 0" />
			<geometry>
				<mesh filename="package://cob3_defs/common/files/meshes/palm.stl"/>
			</geometry>
		</collision>
	</link>
	
	<!-- finger1 -->
	<link name="link_finger11">
		<inertial>
			<origin xyz="0 0 0" rpy="0 0 0"/>
			<mass value="0.1"/>
			<inertia ixx="1"  ixy="0"  ixz="0" iyy="1" iyz="0" izz="1" />
		</inertial>
		<visual>
			<origin xyz="0 0 0" rpy="0 0 0" />
			<geometry>
				<mesh filename="package://cob3_defs/common/files/meshes/knuckle.stl" />
			</geometry>
		</visual>
		<collision>
			<origin xyz="0 0 0" rpy="0 0 0" />
			<geometry>
				<mesh filename="package://cob3_defs/common/files/meshes/knuckle.stl"/>
			</geometry>
		</collision>
	</link>
	
	<link name="link_finger12">
		<inertial>
			<origin xyz="0 0 0" rpy="0 0 0"/>
			<mass value="0.1"/>
			<inertia ixx="1"  ixy="0"  ixz="0" iyy="1" iyz="0" izz="1" />
		</inertial>
		<visual>
			<origin xyz="0 0 0" rpy="0 0 0" />
			<geometry>
				<mesh filename="package://cob3_defs/common/files/meshes/finger.stl" />
			</geometry>
		</visual>
		<collision>
			<origin xyz="0 0 0" rpy="0 0 0" />
			<geometry>
				<mesh filename="package://cob3_defs/common/files/meshes/finger.stl"/>
			</geometry>
		</collision>
	</link>

	<link name="link_finger13">
		<inertial>
			<origin xyz="0 0 0" rpy="0 0 0"/>
			<mass value="0.1"/>
			<inertia ixx="1"  ixy="0"  ixz="0" iyy="1" iyz="0" izz="1" />
		</inertial>
		<visual>
			<origin xyz="0 0 0" rpy="0 0 0" />
			<geometry>
				<mesh filename="package://cob3_defs/common/files/meshes/finger_tip.stl" />
			</geometry>
		</visual>
		<collision>
			<origin xyz="0 0 0" rpy="0 0 0" />
			<geometry>
				<mesh filename="package://cob3_defs/common/files/meshes/finger_tip.stl"/>
			</geometry>
		</collision>
	</link>

	<!-- finger2 -->
	<link name="link_finger21">
		<inertial>
			<origin xyz="0 0 0" rpy="0 0 0"/>
			<mass value="0.1"/>
			<inertia ixx="1"  ixy="0"  ixz="0" iyy="1" iyz="0" izz="1" />
		</inertial>
		<visual>
			<origin xyz="0 0 0" rpy="0 0 0" />
			<geometry>
				<mesh filename="package://cob3_defs/common/files/meshes/knuckle.stl" />
			</geometry>
		</visual>
		<collision>
			<origin xyz="0 0 0" rpy="1.57079633 0 0" />
			<geometry>
				<mesh filename="package://cob3_defs/common/files/meshes/knuckle.stl"/>
			</geometry>
		</collision>
	</link>

	<link name="link_finger22">
		<inertial>
			<origin xyz="0 0 0" rpy="0 0 0"/>
			<mass value="0.1"/>
			<inertia ixx="1"  ixy="0"  ixz="0" iyy="1" iyz="0" izz="1" />
		</inertial>
		<visual>
			<origin xyz="0 0 0" rpy="0 0 0" />
			<geometry>
				<mesh filename="package://cob3_defs/common/files/meshes/finger.stl" />
			</geometry>
		</visual>
		<collision>
			<origin xyz="0 0 0" rpy="0 0 0" />
			<geometry>
				<mesh filename="package://cob3_defs/common/files/meshes/finger.stl"/>
			</geometry>
		</collision>
	</link>

	<link name="link_finger23">
		<inertial>
			<origin xyz="0 0 0" rpy="0 0 0"/>
			<mass value="0.1"/>
			<inertia ixx="1"  ixy="0"  ixz="0" iyy="1" iyz="0" izz="1" />
		</inertial>
		<visual>
			<origin xyz="0 0 0" rpy="0 0 0" />
			<geometry>
				<mesh filename="package://cob3_defs/common/files/meshes/finger_tip.stl" />
			</geometry>
		</visual>
		<collision>
			<origin xyz="0 0 0" rpy="0 0 0" />
			<geometry>
				<mesh filename="package://cob3_defs/common/files/meshes/finger_tip.stl"/>
			</geometry>
		</collision>
	</link>

	<!-- thumb -->
	<link name="link_thumb1">
		<inertial>
			<origin xyz="0 0 0" rpy="0 0 0"/>
			<mass value="0.1"/>
			<inertia ixx="1"  ixy="0"  ixz="0" iyy="1" iyz="0" izz="1" />
		</inertial>
		<visual>
			<origin xyz="0 0 0" rpy="0 0 0" />
			<geometry>
				<mesh filename="package://cob3_defs/common/files/meshes/knuckle.stl" />
			</geometry>
		</visual>
		<collision>
			<origin xyz="0 0 0" rpy="0 0 0" />
			<geometry>
				<mesh filename="package://cob3_defs/common/files/meshes/knuckle.stl"/>
			</geometry>
		</collision>
	</link>

	<link name="link_thumb2">
		<inertial>
			<origin xyz="0 0 0" rpy="0 0 0"/>
			<mass value="0.1"/>	
			<inertia ixx="1"  ixy="0"  ixz="0" iyy="1" iyz="0" izz="1" />
		</inertial>
		<visual>
			<origin xyz="0 0 0" rpy="0 0 0" />
			<geometry>
				<mesh filename="package://cob3_defs/common/files/meshes/finger.stl" />
			</geometry>
		</visual>
		<collision>
			<origin xyz="0 0 0" rpy="0 0 0" />
			<geometry>
				<mesh filename="package://cob3_defs/common/files/meshes/finger.stl"/>
			</geometry>
		</collision>
	</link>
	
	<link name="link_thumb3">
		<inertial>
			<origin xyz="0 0 0" rpy="0 0 0"/>
			<mass value="0.1"/>
			<inertia ixx="1"  ixy="0"  ixz="0" iyy="1" iyz="0" izz="1" />
		</inertial>
		<visual>
			<origin xyz="0 0 0" rpy="0 0 0" />
			<geometry>
				<mesh filename="package://cob3_defs/common/files/meshes/finger_tip.stl" />
			</geometry>
		</visual>
		<collision>
			<origin xyz="0 0 0" rpy="0 0 0" />
			<geometry>
				<mesh filename="package://cob3_defs/common/files/meshes/finger_tip.stl"/>
			</geometry>
		</collision>
	</link>
	
	<!-- define colors for links -->
	<gazebo reference="link_palm">
		<material>Gazebo/Grey</material>
		<turnGravityOff>false</turnGravityOff>
	</gazebo>
	
	<gazebo reference="link_finger11">
		<material>Gazebo/Black</material>
		<turnGravityOff>false</turnGravityOff>
	</gazebo>
	
	<gazebo reference="link_finger12">
		<material>Gazebo/Red</material>
		<turnGravityOff>false</turnGravityOff>
	</gazebo>
	
	<gazebo reference="link_finger13">
		<material>Gazebo/Blue</material>
		<turnGravityOff>false</turnGravityOff>
	</gazebo>

	<gazebo reference="link_finger21">
		<material>Gazebo/Black</material>
		<turnGravityOff>false</turnGravityOff>
	</gazebo>

	<gazebo reference="link_finger22">
		<material>Gazebo/Red</material>
		<turnGravityOff>false</turnGravityOff>
	</gazebo>

	<gazebo reference="link_finger23">
		<material>Gazebo/Blue</material>
		<turnGravityOff>false</turnGravityOff>
	</gazebo>

	<gazebo reference="link_thumb1">
		<material>Gazebo/Black</material>
		<turnGravityOff>false</turnGravityOff>
	</gazebo>
	
	<gazebo reference="link_thumb2">
		<material>Gazebo/Red</material>
		<turnGravityOff>false</turnGravityOff>
	</gazebo>

	<gazebo reference="link_thumb3">
		<material>Gazebo/Blue</material>
		<turnGravityOff>false</turnGravityOff>
	</gazebo>

	<!-- ################################################################################# -->
	<!-- add joints -->

	<!-- palm -->

	<!-- finger1 -->
	<joint name="joint_palm_finger11" type="revolute">
		<origin xyz="0.01905 0.033 0.0745" rpy="0 0 3.159265" />
		<parent link="link_palm"/>
		<child link="link_finger11"/>
		<axis xyz="0 0 1" />
	    <calibration reference_position="0.0"/>
		<limit effort="100" lower="-2" upper="2" velocity="5"/> <!-- rads. effort is N-m applied force. vel is rad/s. -->
	</joint>
 
	<joint name="joint_finger11_finger12" type="revolute">
		<origin xyz="0 0 0.0165" rpy="0 0 0" />
		<parent link="link_finger11"/>
		<child link="link_finger12"/>
		<axis xyz="0 1 0" />
	    <calibration reference_position="0.0"/>
		<limit effort="100" lower="-2" upper="2" velocity="5"/> <!-- rads. effort is N-m applied force. vel is rad/s. -->
	</joint>
 
	<joint name="joint_finger12_finger13" type="revolute">
		<origin xyz="0 0 0.0865" rpy="0 0 0" />
		<parent link="link_finger12"/>
		<child link="link_finger13"/>
		<axis xyz="0 1 0" />
	    <calibration reference_position="0.0"/>
		<limit effort="100" lower="-2" upper="2" velocity="5"/> <!-- rads. effort is N-m applied force. vel is rad/s. -->
	</joint>
 
	<!-- finger2 -->
	<joint name="joint_palm_finger21" type="revolute">
		<origin xyz="0.01905 -0.033 0.0745" rpy="0 0 3.14159265" />
		<parent link="link_palm"/>
		<child link="link_finger21"/>
		<axis xyz="0 0 1" />
	    <calibration reference_position="0.0"/>
		<limit effort="100" lower="-2" upper="2" velocity="5"/> <!-- rads. effort is N-m applied force. vel is rad/s. -->
	</joint>
 
	<joint name="joint_finger21_finger22" type="revolute">
		<origin xyz="0 0 0.0165" rpy="0 0 0" />
		<parent link="link_finger21"/>
		<child link="link_finger22"/>
		<axis xyz="0 1 0" />
	    <calibration reference_position="0.0"/>
		<limit effort="100" lower="-2" upper="2" velocity="5"/> <!-- rads. effort is N-m applied force. vel is rad/s. -->
	</joint>
 
	<joint name="joint_finger22_finger23" type="revolute">
		<origin xyz="0 0 0.0865" rpy="0 0 0" />
		<parent link="link_finger22"/>
		<child link="link_finger23"/>
		<axis xyz="0 1 0" />
	    <calibration reference_position="0.0"/>
		<limit effort="100" lower="-2" upper="2" velocity="5"/> <!-- rads. effort is N-m applied force. vel is rad/s. -->
	</joint>
 
	<!-- thumb -->
	<joint name="joint_palm_thumb1" type="revolute">
		<origin xyz="-0.03811 0 0.0745 " rpy="0 0 0" />
		<parent link="link_palm"/>
		<child link="link_thumb1"/>
		<axis xyz="0 0 1" />
	    <calibration reference_position="0.0"/>
		<limit effort="100" lower="-2" upper="2" velocity="5"/> <!-- rads. effort is N-m applied force. vel is rad/s. -->
	</joint>
 
	<joint name="joint_thumb1_thumb2" type="revolute">
		<origin xyz="0 0 0.0165" rpy="0 0 0" />
		<parent link="link_thumb1"/>
		<child link="link_thumb2"/>
		<axis xyz="0 1 0" />
	    <calibration reference_position="0.0"/>
		<limit effort="100" lower="-2" upper="2" velocity="5"/> <!-- rads. effort is N-m applied force. vel is rad/s. -->
	</joint>
 
	<joint name="joint_thumb2_thumb3" type="revolute">
		<origin xyz="0 0 0.0865" rpy="0 0 0" />
		<parent link="link_thumb2"/>
		<child link="link_thumb3"/>
		<axis xyz="0 1 0" />
	    <calibration reference_position="0.0"/>
		<limit effort="100" lower="-2" upper="2" velocity="5"/> <!-- rads. effort is N-m applied force. vel is rad/s. -->
	</joint>

	<!-- ################################################################################# -->
	<!-- add transmissions -->
	
	<!-- finger1 -->
	<transmission name="trans_palm_finger11" type="SimpleTransmission">
		<actuator name="motor_palm_finger11"/>
		<joint name="joint_palm_finger11"/>
		<mechanicalReduction>1</mechanicalReduction>
	</transmission>
	
	<transmission name="trans_finger11_finger12" type="SimpleTransmission">
		<actuator name="motor_finger11_finger12"/>
		<joint name="joint_finger11_finger12"/>
		<mechanicalReduction>1</mechanicalReduction>
	</transmission>
	
	<transmission name="trans_finger12_finger13" type="SimpleTransmission">
		<actuator name="motor_finger12_finger13"/>
		<joint name="joint_finger12_finger13"/>
		<mechanicalReduction>1</mechanicalReduction>
	</transmission>
	
	<!-- finger2 -->
	<transmission name="trans_palm_finger21" type="SimpleTransmission">
		<actuator name="motor_palm_finger21"/>
		<joint name="joint_palm_finger21"/>
		<mechanicalReduction>1</mechanicalReduction>
	</transmission>
	
	<transmission name="trans_finger21_finger22" type="SimpleTransmission">
		<actuator name="motor_finger21_finger22"/>
		<joint name="joint_finger21_finger22"/>
		<mechanicalReduction>1</mechanicalReduction>
	</transmission>
	
	<transmission name="trans_finger22_finger23" type="SimpleTransmission">
		<actuator name="motor_finger22_finger23"/>
		<joint name="joint_finger22_finger23"/>
		<mechanicalReduction>1</mechanicalReduction>
	</transmission>
	
	<!-- thumb -->
	<transmission name="trans_palm_thumb1" type="SimpleTransmission">
		<actuator name="motor_palm_thumb1"/>
		<joint name="joint_palm_thumb1"/>
		<mechanicalReduction>1</mechanicalReduction>
	</transmission>
	
	<transmission name="trans_thumb1_thumb2" type="SimpleTransmission">
		<actuator name="motor_thumb1_thumb2"/>
		<joint name="joint_thumb1_thumb2"/>
		<mechanicalReduction>1</mechanicalReduction>
	</transmission>
	
	<transmission name="trans_thumb2_thumb3" type="SimpleTransmission">
		<actuator name="motor_thumb2_thumb3"/>
		<joint name="joint_thumb2_thumb3"/>
		<mechanicalReduction>1</mechanicalReduction>
	</transmission>

</robot>
